<?xml version="1.0" encoding="UTF-8" standalone="yes"?>
<robot xmlns:ns2="http://www.ros.org" xmlns:xi="http://www.w3.org/2003/XInclude" name="Eve_base">

  <link name="base">
    <inertial>
      <origin xyz="0.021997 0.006327 -0.006204" rpy="0.0 0.0 0.0"/>
      <mass value="13.647499"/>
      <inertia ixx="0.461101" ixy="-0.004042" ixz="-0.020010" iyy="0.246583" iyz="-0.000110" izz="0.679520"/>
    </inertial>
    <visual>
      <origin xyz="0.0 0.0 0.0" rpy="1.5707963 0.0 1.5707963"/>
      <geometry>
        <mesh filename="package://eve/meshes/base_wheels.obj" scale="1 1 1"/>
        <!-- <box size=".5 .15 .5" /> -->
      </geometry>
    </visual>
   <collision>
     <origin xyz="-0.28 0.0 -0.08" rpy="1.5707963 0.0 1.5707963"/>
     <geometry>
       <sphere radius="0.05"/>
     </geometry>
     <drake_compliance>
        <static_friction>0.0</static_friction>
        <dynamic_friction>0.0</dynamic_friction>
     </drake_compliance>
   </collision>
  </link>


  <joint name="j_l_wheel_y" type="revolute">
    <origin xyz="0.142 0.26983 0.019" rpy="0.0 0.0 0.0"/>
    <parent link="base"/>
    <child link="l_wheel"/>
    <axis xyz="0.0 1.0 0.0"/>
    <limit lower="-1.0E16" upper="1.0E16" effort="-1.0" velocity="1.0"/>
  </joint>
 <transmission name="j_l_wheel_y_trans">
   <type>SimpleTransmission</type>
   <joint name="j_l_wheel_y">
     <hardwareInterface>EffortJointInterface</hardwareInterface>
   </joint>
   <actuator name="j_l_wheel_y_actuator">
   </actuator>
 </transmission>
  <link name="l_wheel">
    <inertial>
      <origin xyz="0.0 0.0 0.0" rpy="0.0 0.0 0.0"/>
      <mass value="1.52693"/>
      <inertia ixx="0.007129" ixy="-0.0" ixz="-0.0" iyy="0.013685" iyz="-0.0" izz="0.007131"/>
    </inertial>
    <visual>
      <origin xyz="0.0 0.0 0.0" rpy="1.5707963 0.0 -1.5707963"/>
      <geometry>
        <mesh filename="package://eve/meshes/wheel.obj" scale="1 1 1"/>
      </geometry>
    </visual>
   <collision>
     <origin xyz="0.0 0.0 0.0" rpy="1.5707963 0.0 0.0"/>
     <geometry>
       <sphere radius="0.15"/>
     </geometry>
     <drake_compliance>
       <static_friction>0.99</static_friction>
       <dynamic_friction>0.99</dynamic_friction>
     </drake_compliance>
   </collision>
  </link>
  <joint name="j_r_wheel_y" type="revolute">
    <origin xyz="0.142 -0.26983 0.019" rpy="0.0 0.0 0.0"/>
    <parent link="base"/>
    <child link="r_wheel"/>
    <axis xyz="0.0 1.0 0.0"/>
    <limit lower="-1.0E16" upper="1.0E16" effort="-1.0" velocity="1.0"/>
  </joint>
 <transmission name="j_r_wheel_y_trans">
   <type>SimpleTransmission</type>
   <joint name="j_r_wheel_y">
     <hardwareInterface>EffortJointInterface</hardwareInterface>
   </joint>
   <actuator name="j_r_wheel_y_actuator">
   </actuator>
 </transmission>
  <link name="r_wheel">
    <inertial>
      <origin xyz="0.0 0.0 0.0" rpy="0.0 0.0 0.0"/>
      <mass value="1.52693"/>
      <inertia ixx="0.007129" ixy="-0.0" ixz="-0.0" iyy="0.013685" iyz="-0.0" izz="0.007131"/>
    </inertial>
    <visual>
      <origin xyz="0.0 0.0 0.0" rpy="1.5707963 0.0 1.5707963"/>
      <geometry>
        <mesh filename="package://eve/meshes/wheel.obj" scale="1 1 1"/>
      </geometry>
    </visual>
   <collision>
     <origin xyz="0.0 0.0 0.0" rpy="1.5707963 0.0 0.0"/>
     <geometry>
       <sphere radius="0.15"/>
     </geometry>
     <drake_compliance>
       <static_friction>0.99</static_friction>
       <dynamic_friction>0.99</dynamic_friction>
     </drake_compliance>
   </collision>
  </link>

</robot>
