<sdf version='1.6'>
  <model name='Eve_base'>
    <link name='base'>
      <pose frame=''>0 0 0 0 -0 0</pose>
      <inertial>
        <pose frame=''>0.021997 0.006327 -0.006204 0 -0 0</pose>
        <mass>13.6475</mass>
        <inertia>
          <ixx>0.461101</ixx>
          <ixy>-0.004042</ixy>
          <ixz>-0.02001</ixz>
          <iyy>0.246583</iyy>
          <iyz>-0.00011</iyz>
          <izz>0.67952</izz>
        </inertia>
      </inertial>
      <collision name='base_collision'>
        <pose frame=''>-0.28 0 -0.08 1.5708 -0 1.5708</pose>
        <geometry>
          <sphere>
            <radius>0.05</radius>
          </sphere>
        </geometry>
      </collision>
      <visual name='base_visual'>
        <pose frame=''>0 0 0 1.5708 -0 1.5708</pose>
        <geometry>
          <mesh>
            <scale>1 1 1</scale>
            <uri>model://eve/meshes/base_wheels.obj</uri>
          </mesh>
        </geometry>
      </visual>
    </link>
    <link name='l_wheel'>
      <pose frame=''>0.142 0.26983 0.019 0 -0 0</pose>
      <inertial>
        <pose frame=''>0 0 0 0 -0 0</pose>
        <mass>1.52693</mass>
        <inertia>
          <ixx>0.007129</ixx>
          <ixy>-0</ixy>
          <ixz>-0</ixz>
          <iyy>0.013685</iyy>
          <iyz>-0</iyz>
          <izz>0.007131</izz>
        </inertia>
      </inertial>
      <collision name='l_wheel_collision'>
        <pose frame=''>0 0 0 1.5708 -0 0</pose>
        <geometry>
          <sphere>
            <radius>0.15</radius>
          </sphere>
        </geometry>
      </collision>
      <visual name='l_wheel_visual'>
        <pose frame=''>0 0 0 1.5708 0 -1.5708</pose>
        <geometry>
          <mesh>
            <scale>1 1 1</scale>
            <uri>model://eve/meshes/wheel.obj</uri>
          </mesh>
        </geometry>
      </visual>
    </link>
    <joint name='j_l_wheel_y' type='revolute'>
      <child>l_wheel</child>
      <parent>base</parent>
      <axis>
        <xyz>0 1 0</xyz>
        <limit>
          <lower>-1e+16</lower>
          <upper>1e+16</upper>
          <effort>-1</effort>
          <velocity>1</velocity>
        </limit>
        <dynamics>
          <spring_reference>0</spring_reference>
          <spring_stiffness>0</spring_stiffness>
        </dynamics>
        <use_parent_model_frame>1</use_parent_model_frame>
      </axis>
    </joint>
    <link name='r_wheel'>
      <pose frame=''>0.142 -0.26983 0.019 0 -0 0</pose>
      <inertial>
        <pose frame=''>0 0 0 0 -0 0</pose>
        <mass>1.52693</mass>
        <inertia>
          <ixx>0.007129</ixx>
          <ixy>-0</ixy>
          <ixz>-0</ixz>
          <iyy>0.013685</iyy>
          <iyz>-0</iyz>
          <izz>0.007131</izz>
        </inertia>
      </inertial>
      <collision name='r_wheel_collision'>
        <pose frame=''>0 0 0 1.5708 -0 0</pose>
        <geometry>
          <sphere>
            <radius>0.15</radius>
          </sphere>
        </geometry>
      </collision>
      <visual name='r_wheel_visual'>
        <pose frame=''>0 0 0 1.5708 -0 1.5708</pose>
        <geometry>
          <mesh>
            <scale>1 1 1</scale>
            <uri>model://eve/meshes/wheel.obj</uri>
          </mesh>
        </geometry>
      </visual>
    </link>
    <joint name='j_r_wheel_y' type='revolute'>
      <child>r_wheel</child>
      <parent>base</parent>
      <axis>
        <xyz>0 1 0</xyz>
        <limit>
          <lower>-1e+16</lower>
          <upper>1e+16</upper>
          <effort>-1</effort>
          <velocity>1</velocity>
        </limit>
        <dynamics>
          <spring_reference>0</spring_reference>
          <spring_stiffness>0</spring_stiffness>
        </dynamics>
        <use_parent_model_frame>1</use_parent_model_frame>
      </axis>
    </joint>
  </model>
</sdf>
