<sdf version='1.6'>
  <model name='Eve_base'>
    <link name='shin'>
      <pose frame=''>0 0 0 0 -0 0</pose>
      <inertial>
        <pose frame=''>0.019484 6.7e-05 0.212676 0 -0 0</pose>
        <mass>10.8949</mass>
        <inertia>
          <ixx>0.191988</ixx>
          <ixy>-0.000208</ixy>
          <ixz>0.005202</ixz>
          <iyy>0.176793</iyy>
          <iyz>-0.000345</iyz>
          <izz>0.049718</izz>
        </inertia>
      </inertial>
      <visual name='shin_visual'>
        <pose frame=''>0 0 0.38 1.5708 -0 1.5708</pose>
        <geometry>
          <mesh>
            <scale>1 1 1</scale>
            <uri>model://eve/meshes/shin.obj</uri>
          </mesh>
        </geometry>
      </visual>
    </link>

    <joint name='j_ankle_y' type='revolute'>
      <child>shin</child>
      <parent>ankle_y_link</parent>
      <axis>
        <xyz>0 1 0</xyz>
        <limit>
          <lower>-0.174533</lower>
          <upper>1.57</upper>
          <effort>1</effort>
          <velocity>1</velocity>
        </limit>
        <dynamics>
          <spring_reference>0</spring_reference>
          <spring_stiffness>0</spring_stiffness>
        </dynamics>
        <use_parent_model_frame>1</use_parent_model_frame>
      </axis>
    </joint>

    <link name='ankle_y_link'>
      <pose frame=''>0 0 0 0 -0 0</pose>
      <inertial>
        <pose frame=''>-0.017821 0.001497 -0.000649 0 -0 0</pose>
        <mass>2.65619</mass>
        <inertia>
          <ixx>0.010249</ixx>
          <ixy>-8.2e-05</ixy>
          <ixz>0.000265</ixz>
          <iyy>0.009117</iyy>
          <iyz>9e-06</iyz>
          <izz>0.013843</izz>
        </inertia>
      </inertial>
      <visual name='ankle_y_link_visual'>
        <pose frame=''>0 0 0 1.5708 -0 1.5708</pose>
        <geometry>
          <mesh>
            <scale>1 1 1</scale>
            <uri>model://eve/meshes/ankle.obj</uri>
          </mesh>
        </geometry>
      </visual>
    </link>

    <joint name='j_ankle_x' type='revolute'>
      <child>ankle_y_link</child>
      <parent>base</parent>
      <axis>
        <xyz>1 0 0</xyz>
        <limit>
          <lower>-0.523599</lower>
          <upper>0.523599</upper>
          <effort>1</effort>
          <velocity>1</velocity>
        </limit>
        <dynamics>
          <spring_reference>0</spring_reference>
          <spring_stiffness>0</spring_stiffness>
        </dynamics>
        <use_parent_model_frame>1</use_parent_model_frame>
      </axis>
    </joint>
    <link name='base'>
      <pose frame=''>0 0 0 0 -0 0</pose>
      <inertial>
        <pose frame=''>0.021997 0.006327 -0.006204 0 -0 0</pose>
        <mass>13.6475</mass>
        <inertia>
          <ixx>0.461101</ixx>
          <ixy>-0.004042</ixy>
          <ixz>-0.02001</ixz>
          <iyy>0.246583</iyy>
          <iyz>-0.00011</iyz>
          <izz>0.67952</izz>
        </inertia>
      </inertial>
      <visual name='base_visual'>
        <pose frame=''>0 0 0 1.5708 -0 1.5708</pose>
        <geometry>
          <mesh>
            <scale>1 1 1</scale>
            <uri>model://eve/meshes/base_wheels.obj</uri>
          </mesh>
        </geometry>
      </visual>
    </link>
  </model>
</sdf>
